[2021-07-14 14:22:38,415] {taskinstance.py:876} INFO - Dependencies all met for <TaskInstance: psotgrressdftest.extract_trends 2021-07-14T14:22:23.832516+00:00 [queued]>
[2021-07-14 14:22:38,494] {taskinstance.py:876} INFO - Dependencies all met for <TaskInstance: psotgrressdftest.extract_trends 2021-07-14T14:22:23.832516+00:00 [queued]>
[2021-07-14 14:22:38,495] {taskinstance.py:1067} INFO - 
--------------------------------------------------------------------------------
[2021-07-14 14:22:38,496] {taskinstance.py:1068} INFO - Starting attempt 1 of 1
[2021-07-14 14:22:38,498] {taskinstance.py:1069} INFO - 
--------------------------------------------------------------------------------
[2021-07-14 14:22:38,526] {taskinstance.py:1087} INFO - Executing <Task(PythonOperator): extract_trends> on 2021-07-14T14:22:23.832516+00:00
[2021-07-14 14:22:38,570] {standard_task_runner.py:52} INFO - Started process 4351 to run task
[2021-07-14 14:22:38,584] {standard_task_runner.py:76} INFO - Running: ['***', 'tasks', 'run', 'psotgrressdftest', 'extract_trends', '2021-07-14T14:22:23.832516+00:00', '--job-id', '262', '--pool', 'default_pool', '--raw', '--subdir', 'DAGS_FOLDER/POSTGRESRSERS.py', '--cfg-path', '/tmp/tmp635ernwk', '--error-file', '/tmp/tmpbyvr0_7q']
[2021-07-14 14:22:38,586] {standard_task_runner.py:77} INFO - Job 262: Subtask extract_trends
[2021-07-14 14:22:38,765] {logging_mixin.py:104} INFO - Running <TaskInstance: psotgrressdftest.extract_trends 2021-07-14T14:22:23.832516+00:00 [running]> on host a2cbcfd4d6f4
[2021-07-14 14:22:38,955] {taskinstance.py:1282} INFO - Exporting the following env vars:
AIRFLOW_CTX_DAG_OWNER=***
AIRFLOW_CTX_DAG_ID=psotgrressdftest
AIRFLOW_CTX_TASK_ID=extract_trends
AIRFLOW_CTX_EXECUTION_DATE=2021-07-14T14:22:23.832516+00:00
AIRFLOW_CTX_DAG_RUN_ID=manual__2021-07-14T14:22:23.832516+00:00
[2021-07-14 14:22:39,028] {logging_mixin.py:104} INFO - ['A', 'A', 'R', 'T', 'I', 'I', 'N', 'D', '.', 'N', 'S']
[2021-07-14 14:22:40,380] {taskinstance.py:1481} ERROR - Task failed with exception
Traceback (most recent call last):
  File "/home/airflow/.local/lib/python3.6/site-packages/airflow/models/taskinstance.py", line 1137, in _run_raw_task
    self._prepare_and_execute_task_with_callbacks(context, task)
  File "/home/airflow/.local/lib/python3.6/site-packages/airflow/models/taskinstance.py", line 1311, in _prepare_and_execute_task_with_callbacks
    result = self._execute_task(context, task_copy)
  File "/home/airflow/.local/lib/python3.6/site-packages/airflow/models/taskinstance.py", line 1341, in _execute_task
    result = task_copy.execute(context=context)
  File "/home/airflow/.local/lib/python3.6/site-packages/airflow/operators/python.py", line 150, in execute
    return_value = self.execute_callable()
  File "/home/airflow/.local/lib/python3.6/site-packages/airflow/operators/python.py", line 161, in execute_callable
    return self.python_callable(*self.op_args, **self.op_kwargs)
  File "/opt/airflow/dags/POSTGRESRSERS.py", line 145, in extract_trends
    pytrends.build_payload(ticker, cat = 0 , timeframe = 'now 1-d' , geo = i , gprop='')
  File "/home/airflow/.local/lib/python3.6/site-packages/pytrends/request.py", line 169, in build_payload
    self._tokens()
  File "/home/airflow/.local/lib/python3.6/site-packages/pytrends/request.py", line 179, in _tokens
    trim_chars=4,
  File "/home/airflow/.local/lib/python3.6/site-packages/pytrends/request.py", line 148, in _get_data
    response=response)
pytrends.exceptions.ResponseError: The request failed: Google returned a response with code 400.
[2021-07-14 14:22:40,406] {taskinstance.py:1531} INFO - Marking task as FAILED. dag_id=psotgrressdftest, task_id=extract_trends, execution_date=20210714T142223, start_date=20210714T142238, end_date=20210714T142240
[2021-07-14 14:22:40,509] {local_task_job.py:151} INFO - Task exited with return code 1
