[2021-07-14 13:31:15,011] {taskinstance.py:876} INFO - Dependencies all met for <TaskInstance: psotgrressdftest.extract_trends 2021-07-14T13:31:00.480216+00:00 [queued]>
[2021-07-14 13:31:15,212] {taskinstance.py:876} INFO - Dependencies all met for <TaskInstance: psotgrressdftest.extract_trends 2021-07-14T13:31:00.480216+00:00 [queued]>
[2021-07-14 13:31:15,228] {taskinstance.py:1067} INFO - 
--------------------------------------------------------------------------------
[2021-07-14 13:31:15,245] {taskinstance.py:1068} INFO - Starting attempt 1 of 1
[2021-07-14 13:31:15,254] {taskinstance.py:1069} INFO - 
--------------------------------------------------------------------------------
[2021-07-14 13:31:15,304] {taskinstance.py:1087} INFO - Executing <Task(PythonOperator): extract_trends> on 2021-07-14T13:31:00.480216+00:00
[2021-07-14 13:31:15,346] {standard_task_runner.py:52} INFO - Started process 1129 to run task
[2021-07-14 13:31:15,374] {standard_task_runner.py:76} INFO - Running: ['***', 'tasks', 'run', 'psotgrressdftest', 'extract_trends', '2021-07-14T13:31:00.480216+00:00', '--job-id', '186', '--pool', 'default_pool', '--raw', '--subdir', 'DAGS_FOLDER/POSTGRESRSERS.py', '--cfg-path', '/tmp/tmpo1w3i8e5', '--error-file', '/tmp/tmpeuayx_38']
[2021-07-14 13:31:15,383] {standard_task_runner.py:77} INFO - Job 186: Subtask extract_trends
[2021-07-14 13:31:15,705] {logging_mixin.py:104} INFO - Running <TaskInstance: psotgrressdftest.extract_trends 2021-07-14T13:31:00.480216+00:00 [running]> on host a2cbcfd4d6f4
[2021-07-14 13:31:16,253] {taskinstance.py:1282} INFO - Exporting the following env vars:
AIRFLOW_CTX_DAG_OWNER=***
AIRFLOW_CTX_DAG_ID=psotgrressdftest
AIRFLOW_CTX_TASK_ID=extract_trends
AIRFLOW_CTX_EXECUTION_DATE=2021-07-14T13:31:00.480216+00:00
AIRFLOW_CTX_DAG_RUN_ID=manual__2021-07-14T13:31:00.480216+00:00
[2021-07-14 13:31:16,300] {logging_mixin.py:104} INFO - 20MICRONS
[2021-07-14 13:31:19,067] {taskinstance.py:1481} ERROR - Task failed with exception
Traceback (most recent call last):
  File "/home/airflow/.local/lib/python3.6/site-packages/airflow/models/taskinstance.py", line 1137, in _run_raw_task
    self._prepare_and_execute_task_with_callbacks(context, task)
  File "/home/airflow/.local/lib/python3.6/site-packages/airflow/models/taskinstance.py", line 1311, in _prepare_and_execute_task_with_callbacks
    result = self._execute_task(context, task_copy)
  File "/home/airflow/.local/lib/python3.6/site-packages/airflow/models/taskinstance.py", line 1341, in _execute_task
    result = task_copy.execute(context=context)
  File "/home/airflow/.local/lib/python3.6/site-packages/airflow/operators/python.py", line 150, in execute
    return_value = self.execute_callable()
  File "/home/airflow/.local/lib/python3.6/site-packages/airflow/operators/python.py", line 161, in execute_callable
    return self.python_callable(*self.op_args, **self.op_kwargs)
  File "/opt/airflow/dags/POSTGRESRSERS.py", line 141, in extract_trends
    pytrends.build_payload(ticker, cat = 0 , timeframe = 'now 1-d' , geo = i , gprop='')
  File "/home/airflow/.local/lib/python3.6/site-packages/pytrends/request.py", line 169, in build_payload
    self._tokens()
  File "/home/airflow/.local/lib/python3.6/site-packages/pytrends/request.py", line 179, in _tokens
    trim_chars=4,
  File "/home/airflow/.local/lib/python3.6/site-packages/pytrends/request.py", line 148, in _get_data
    response=response)
pytrends.exceptions.ResponseError: The request failed: Google returned a response with code 400.
[2021-07-14 13:31:19,222] {taskinstance.py:1531} INFO - Marking task as FAILED. dag_id=psotgrressdftest, task_id=extract_trends, execution_date=20210714T133100, start_date=20210714T133115, end_date=20210714T133119
[2021-07-14 13:31:19,370] {local_task_job.py:151} INFO - Task exited with return code 1
