[2021-07-16 10:32:36,944] {taskinstance.py:876} INFO - Dependencies all met for <TaskInstance: psotgrressdftest.news_postgres_table 2021-07-16T10:31:31.698359+00:00 [queued]>
[2021-07-16 10:32:36,973] {taskinstance.py:876} INFO - Dependencies all met for <TaskInstance: psotgrressdftest.news_postgres_table 2021-07-16T10:31:31.698359+00:00 [queued]>
[2021-07-16 10:32:36,975] {taskinstance.py:1067} INFO - 
--------------------------------------------------------------------------------
[2021-07-16 10:32:36,976] {taskinstance.py:1068} INFO - Starting attempt 1 of 1
[2021-07-16 10:32:36,976] {taskinstance.py:1069} INFO - 
--------------------------------------------------------------------------------
[2021-07-16 10:32:37,002] {taskinstance.py:1087} INFO - Executing <Task(PythonOperator): news_postgres_table> on 2021-07-16T10:31:31.698359+00:00
[2021-07-16 10:32:37,017] {standard_task_runner.py:52} INFO - Started process 1616 to run task
[2021-07-16 10:32:37,023] {standard_task_runner.py:76} INFO - Running: ['***', 'tasks', 'run', 'psotgrressdftest', 'news_postgres_table', '2021-07-16T10:31:31.698359+00:00', '--job-id', '554', '--pool', 'default_pool', '--raw', '--subdir', 'DAGS_FOLDER/POSTGRESRSERS.py', '--cfg-path', '/tmp/tmpgjp0h79y', '--error-file', '/tmp/tmpvu8n8n6u']
[2021-07-16 10:32:37,025] {standard_task_runner.py:77} INFO - Job 554: Subtask news_postgres_table
[2021-07-16 10:32:37,101] {logging_mixin.py:104} INFO - Running <TaskInstance: psotgrressdftest.news_postgres_table 2021-07-16T10:31:31.698359+00:00 [running]> on host a2cbcfd4d6f4
[2021-07-16 10:32:37,225] {taskinstance.py:1282} INFO - Exporting the following env vars:
AIRFLOW_CTX_DAG_OWNER=***
AIRFLOW_CTX_DAG_ID=psotgrressdftest
AIRFLOW_CTX_TASK_ID=news_postgres_table
AIRFLOW_CTX_EXECUTION_DATE=2021-07-16T10:31:31.698359+00:00
AIRFLOW_CTX_DAG_RUN_ID=manual__2021-07-16T10:31:28.293000+00:00
[2021-07-16 10:32:37,451] {taskinstance.py:1481} ERROR - Task failed with exception
Traceback (most recent call last):
  File "/home/airflow/.local/lib/python3.6/site-packages/pandas/core/indexes/base.py", line 2898, in get_loc
    return self._engine.get_loc(casted_key)
  File "pandas/_libs/index.pyx", line 70, in pandas._libs.index.IndexEngine.get_loc
  File "pandas/_libs/index.pyx", line 101, in pandas._libs.index.IndexEngine.get_loc
  File "pandas/_libs/hashtable_class_helper.pxi", line 1675, in pandas._libs.hashtable.PyObjectHashTable.get_item
  File "pandas/_libs/hashtable_class_helper.pxi", line 1683, in pandas._libs.hashtable.PyObjectHashTable.get_item
KeyError: 0

The above exception was the direct cause of the following exception:

Traceback (most recent call last):
  File "/home/airflow/.local/lib/python3.6/site-packages/airflow/models/taskinstance.py", line 1137, in _run_raw_task
    self._prepare_and_execute_task_with_callbacks(context, task)
  File "/home/airflow/.local/lib/python3.6/site-packages/airflow/models/taskinstance.py", line 1311, in _prepare_and_execute_task_with_callbacks
    result = self._execute_task(context, task_copy)
  File "/home/airflow/.local/lib/python3.6/site-packages/airflow/models/taskinstance.py", line 1341, in _execute_task
    result = task_copy.execute(context=context)
  File "/home/airflow/.local/lib/python3.6/site-packages/airflow/operators/python.py", line 150, in execute
    return_value = self.execute_callable()
  File "/home/airflow/.local/lib/python3.6/site-packages/airflow/operators/python.py", line 161, in execute_callable
    return self.python_callable(*self.op_args, **self.op_kwargs)
  File "/opt/airflow/dags/POSTGRESRSERS.py", line 106, in news_postgres_table
    df1['compound'] = df1[0].apply(f)
  File "/home/airflow/.local/lib/python3.6/site-packages/pandas/core/frame.py", line 2906, in __getitem__
    indexer = self.columns.get_loc(key)
  File "/home/airflow/.local/lib/python3.6/site-packages/pandas/core/indexes/base.py", line 2900, in get_loc
    raise KeyError(key) from err
KeyError: 0
[2021-07-16 10:32:37,464] {taskinstance.py:1531} INFO - Marking task as FAILED. dag_id=psotgrressdftest, task_id=news_postgres_table, execution_date=20210716T103131, start_date=20210716T103236, end_date=20210716T103237
[2021-07-16 10:32:37,517] {local_task_job.py:151} INFO - Task exited with return code 1
