[2021-07-14 13:54:47,389] {taskinstance.py:876} INFO - Dependencies all met for <TaskInstance: psotgrressdftest.transform_trends 2021-07-14T13:53:40.635638+00:00 [queued]>
[2021-07-14 13:54:47,518] {taskinstance.py:876} INFO - Dependencies all met for <TaskInstance: psotgrressdftest.transform_trends 2021-07-14T13:53:40.635638+00:00 [queued]>
[2021-07-14 13:54:47,521] {taskinstance.py:1067} INFO - 
--------------------------------------------------------------------------------
[2021-07-14 13:54:47,523] {taskinstance.py:1068} INFO - Starting attempt 1 of 1
[2021-07-14 13:54:47,527] {taskinstance.py:1069} INFO - 
--------------------------------------------------------------------------------
[2021-07-14 13:54:47,660] {taskinstance.py:1087} INFO - Executing <Task(PythonOperator): transform_trends> on 2021-07-14T13:53:40.635638+00:00
[2021-07-14 13:54:47,804] {standard_task_runner.py:52} INFO - Started process 2506 to run task
[2021-07-14 13:54:47,910] {standard_task_runner.py:76} INFO - Running: ['***', 'tasks', 'run', 'psotgrressdftest', 'transform_trends', '2021-07-14T13:53:40.635638+00:00', '--job-id', '209', '--pool', 'default_pool', '--raw', '--subdir', 'DAGS_FOLDER/POSTGRESRSERS.py', '--cfg-path', '/tmp/tmp1cqcjhaq', '--error-file', '/tmp/tmp9tmgpc3e']
[2021-07-14 13:54:47,913] {standard_task_runner.py:77} INFO - Job 209: Subtask transform_trends
[2021-07-14 13:54:48,291] {logging_mixin.py:104} INFO - Running <TaskInstance: psotgrressdftest.transform_trends 2021-07-14T13:53:40.635638+00:00 [running]> on host a2cbcfd4d6f4
[2021-07-14 13:54:48,583] {taskinstance.py:1282} INFO - Exporting the following env vars:
AIRFLOW_CTX_DAG_OWNER=***
AIRFLOW_CTX_DAG_ID=psotgrressdftest
AIRFLOW_CTX_TASK_ID=transform_trends
AIRFLOW_CTX_EXECUTION_DATE=2021-07-14T13:53:40.635638+00:00
AIRFLOW_CTX_DAG_RUN_ID=manual__2021-07-14T13:53:40.635638+00:00
[2021-07-14 13:54:48,659] {taskinstance.py:1481} ERROR - Task failed with exception
Traceback (most recent call last):
  File "/home/airflow/.local/lib/python3.6/site-packages/airflow/models/taskinstance.py", line 1137, in _run_raw_task
    self._prepare_and_execute_task_with_callbacks(context, task)
  File "/home/airflow/.local/lib/python3.6/site-packages/airflow/models/taskinstance.py", line 1311, in _prepare_and_execute_task_with_callbacks
    result = self._execute_task(context, task_copy)
  File "/home/airflow/.local/lib/python3.6/site-packages/airflow/models/taskinstance.py", line 1341, in _execute_task
    result = task_copy.execute(context=context)
  File "/home/airflow/.local/lib/python3.6/site-packages/airflow/operators/python.py", line 150, in execute
    return_value = self.execute_callable()
  File "/home/airflow/.local/lib/python3.6/site-packages/airflow/operators/python.py", line 161, in execute_callable
    return self.python_callable(*self.op_args, **self.op_kwargs)
  File "/opt/airflow/dags/POSTGRESRSERS.py", line 160, in transform_trends
    cur.execute(create_table)
psycopg2.DataError: NUMERIC scale 9 must be between 0 and precision 5
LINE 1: ...STS googleTrends_AAPL(date DATE, numberOfSearches NUMERIC(5,...
                                                             ^

[2021-07-14 13:54:48,697] {taskinstance.py:1531} INFO - Marking task as FAILED. dag_id=psotgrressdftest, task_id=transform_trends, execution_date=20210714T135340, start_date=20210714T135447, end_date=20210714T135448
[2021-07-14 13:54:48,857] {local_task_job.py:151} INFO - Task exited with return code 1
