[2021-07-12 14:49:48,978] {taskinstance.py:876} INFO - Dependencies all met for <TaskInstance: ticker_yahoo.extract_task 2021-07-12T14:49:40.794321+00:00 [queued]>
[2021-07-12 14:49:49,256] {taskinstance.py:876} INFO - Dependencies all met for <TaskInstance: ticker_yahoo.extract_task 2021-07-12T14:49:40.794321+00:00 [queued]>
[2021-07-12 14:49:49,259] {taskinstance.py:1067} INFO - 
--------------------------------------------------------------------------------
[2021-07-12 14:49:49,268] {taskinstance.py:1068} INFO - Starting attempt 1 of 2
[2021-07-12 14:49:49,270] {taskinstance.py:1069} INFO - 
--------------------------------------------------------------------------------
[2021-07-12 14:49:49,405] {taskinstance.py:1087} INFO - Executing <Task(PythonOperator): extract_task> on 2021-07-12T14:49:40.794321+00:00
[2021-07-12 14:49:49,553] {standard_task_runner.py:52} INFO - Started process 4488 to run task
[2021-07-12 14:49:49,601] {standard_task_runner.py:76} INFO - Running: ['***', 'tasks', 'run', 'ticker_yahoo', 'extract_task', '2021-07-12T14:49:40.794321+00:00', '--job-id', '34', '--pool', 'default_pool', '--raw', '--subdir', 'DAGS_FOLDER/seleniumtest.py', '--cfg-path', '/tmp/tmpbza6qfh2', '--error-file', '/tmp/tmp_noe2_c2']
[2021-07-12 14:49:49,610] {standard_task_runner.py:77} INFO - Job 34: Subtask extract_task
[2021-07-12 14:49:49,989] {logging_mixin.py:104} INFO - Running <TaskInstance: ticker_yahoo.extract_task 2021-07-12T14:49:40.794321+00:00 [running]> on host f29b1d03ad56
[2021-07-12 14:49:50,377] {taskinstance.py:1282} INFO - Exporting the following env vars:
AIRFLOW_CTX_DAG_OWNER=***
AIRFLOW_CTX_DAG_ID=ticker_yahoo
AIRFLOW_CTX_TASK_ID=extract_task
AIRFLOW_CTX_EXECUTION_DATE=2021-07-12T14:49:40.794321+00:00
AIRFLOW_CTX_DAG_RUN_ID=manual__2021-07-12T14:49:40.794321+00:00
[2021-07-12 14:51:58,747] {taskinstance.py:1481} ERROR - Task failed with exception
Traceback (most recent call last):
  File "/home/airflow/.local/lib/python3.6/site-packages/airflow/models/taskinstance.py", line 1137, in _run_raw_task
    self._prepare_and_execute_task_with_callbacks(context, task)
  File "/home/airflow/.local/lib/python3.6/site-packages/airflow/models/taskinstance.py", line 1311, in _prepare_and_execute_task_with_callbacks
    result = self._execute_task(context, task_copy)
  File "/home/airflow/.local/lib/python3.6/site-packages/airflow/models/taskinstance.py", line 1341, in _execute_task
    result = task_copy.execute(context=context)
  File "/home/airflow/.local/lib/python3.6/site-packages/airflow/operators/python.py", line 150, in execute
    return_value = self.execute_callable()
  File "/home/airflow/.local/lib/python3.6/site-packages/airflow/operators/python.py", line 161, in execute_callable
    return self.python_callable(*self.op_args, **self.op_kwargs)
  File "/opt/airflow/dags/seleniumtest.py", line 62, in extract
    print("AAAAAAAAAAAAAAAAAAAAAAAAAAAAAAAAAAA" + companyname)
TypeError: must be str, not list
[2021-07-12 14:51:58,995] {taskinstance.py:1531} INFO - Marking task as UP_FOR_RETRY. dag_id=ticker_yahoo, task_id=extract_task, execution_date=20210712T144940, start_date=20210712T144949, end_date=20210712T145158
[2021-07-12 14:52:00,399] {local_task_job.py:151} INFO - Task exited with return code 1
