[2021-07-13 09:10:06,348] {taskinstance.py:876} INFO - Dependencies all met for <TaskInstance: psotgrressdftest.tweets_postgres_table 2021-07-13T09:09:28.184121+00:00 [queued]>
[2021-07-13 09:10:06,501] {taskinstance.py:876} INFO - Dependencies all met for <TaskInstance: psotgrressdftest.tweets_postgres_table 2021-07-13T09:09:28.184121+00:00 [queued]>
[2021-07-13 09:10:06,506] {taskinstance.py:1067} INFO - 
--------------------------------------------------------------------------------
[2021-07-13 09:10:06,509] {taskinstance.py:1068} INFO - Starting attempt 1 of 1
[2021-07-13 09:10:06,513] {taskinstance.py:1069} INFO - 
--------------------------------------------------------------------------------
[2021-07-13 09:10:06,569] {taskinstance.py:1087} INFO - Executing <Task(PythonOperator): tweets_postgres_table> on 2021-07-13T09:09:28.184121+00:00
[2021-07-13 09:10:06,605] {standard_task_runner.py:52} INFO - Started process 890 to run task
[2021-07-13 09:10:06,631] {standard_task_runner.py:76} INFO - Running: ['***', 'tasks', 'run', 'psotgrressdftest', 'tweets_postgres_table', '2021-07-13T09:09:28.184121+00:00', '--job-id', '156', '--pool', 'default_pool', '--raw', '--subdir', 'DAGS_FOLDER/POSTGRESRSERS.py', '--cfg-path', '/tmp/tmpfzb1s0mi', '--error-file', '/tmp/tmpqy53yrw0']
[2021-07-13 09:10:06,641] {standard_task_runner.py:77} INFO - Job 156: Subtask tweets_postgres_table
[2021-07-13 09:10:07,057] {logging_mixin.py:104} INFO - Running <TaskInstance: psotgrressdftest.tweets_postgres_table 2021-07-13T09:09:28.184121+00:00 [running]> on host a2cbcfd4d6f4
[2021-07-13 09:10:07,341] {taskinstance.py:1282} INFO - Exporting the following env vars:
AIRFLOW_CTX_DAG_OWNER=***
AIRFLOW_CTX_DAG_ID=psotgrressdftest
AIRFLOW_CTX_TASK_ID=tweets_postgres_table
AIRFLOW_CTX_EXECUTION_DATE=2021-07-13T09:09:28.184121+00:00
AIRFLOW_CTX_DAG_RUN_ID=manual__2021-07-13T09:09:28.184121+00:00
[2021-07-13 09:10:07,599] {taskinstance.py:1481} ERROR - Task failed with exception
Traceback (most recent call last):
  File "/home/airflow/.local/lib/python3.6/site-packages/pandas/core/indexes/base.py", line 2898, in get_loc
    return self._engine.get_loc(casted_key)
  File "pandas/_libs/index.pyx", line 70, in pandas._libs.index.IndexEngine.get_loc
  File "pandas/_libs/index.pyx", line 101, in pandas._libs.index.IndexEngine.get_loc
  File "pandas/_libs/hashtable_class_helper.pxi", line 1675, in pandas._libs.hashtable.PyObjectHashTable.get_item
  File "pandas/_libs/hashtable_class_helper.pxi", line 1683, in pandas._libs.hashtable.PyObjectHashTable.get_item
KeyError: 0

The above exception was the direct cause of the following exception:

Traceback (most recent call last):
  File "/home/airflow/.local/lib/python3.6/site-packages/airflow/models/taskinstance.py", line 1137, in _run_raw_task
    self._prepare_and_execute_task_with_callbacks(context, task)
  File "/home/airflow/.local/lib/python3.6/site-packages/airflow/models/taskinstance.py", line 1311, in _prepare_and_execute_task_with_callbacks
    result = self._execute_task(context, task_copy)
  File "/home/airflow/.local/lib/python3.6/site-packages/airflow/models/taskinstance.py", line 1341, in _execute_task
    result = task_copy.execute(context=context)
  File "/home/airflow/.local/lib/python3.6/site-packages/airflow/operators/python.py", line 150, in execute
    return_value = self.execute_callable()
  File "/home/airflow/.local/lib/python3.6/site-packages/airflow/operators/python.py", line 161, in execute_callable
    return self.python_callable(*self.op_args, **self.op_kwargs)
  File "/opt/airflow/dags/POSTGRESRSERS.py", line 179, in tweets_postgres_table
    df1['compound'] = df1[0].apply(f)
  File "/home/airflow/.local/lib/python3.6/site-packages/pandas/core/frame.py", line 2906, in __getitem__
    indexer = self.columns.get_loc(key)
  File "/home/airflow/.local/lib/python3.6/site-packages/pandas/core/indexes/base.py", line 2900, in get_loc
    raise KeyError(key) from err
KeyError: 0
[2021-07-13 09:10:07,724] {taskinstance.py:1531} INFO - Marking task as FAILED. dag_id=psotgrressdftest, task_id=tweets_postgres_table, execution_date=20210713T090928, start_date=20210713T091006, end_date=20210713T091007
[2021-07-13 09:10:07,963] {local_task_job.py:151} INFO - Task exited with return code 1
