[2021-07-14 13:34:06,926] {taskinstance.py:876} INFO - Dependencies all met for <TaskInstance: psotgrressdftest.extract_trends 2021-07-14T13:33:48.199928+00:00 [queued]>
[2021-07-14 13:34:07,729] {taskinstance.py:876} INFO - Dependencies all met for <TaskInstance: psotgrressdftest.extract_trends 2021-07-14T13:33:48.199928+00:00 [queued]>
[2021-07-14 13:34:07,738] {taskinstance.py:1067} INFO - 
--------------------------------------------------------------------------------
[2021-07-14 13:34:07,739] {taskinstance.py:1068} INFO - Starting attempt 1 of 1
[2021-07-14 13:34:07,742] {taskinstance.py:1069} INFO - 
--------------------------------------------------------------------------------
[2021-07-14 13:34:07,795] {taskinstance.py:1087} INFO - Executing <Task(PythonOperator): extract_trends> on 2021-07-14T13:33:48.199928+00:00
[2021-07-14 13:34:07,868] {standard_task_runner.py:52} INFO - Started process 1306 to run task
[2021-07-14 13:34:07,901] {standard_task_runner.py:76} INFO - Running: ['***', 'tasks', 'run', 'psotgrressdftest', 'extract_trends', '2021-07-14T13:33:48.199928+00:00', '--job-id', '192', '--pool', 'default_pool', '--raw', '--subdir', 'DAGS_FOLDER/POSTGRESRSERS.py', '--cfg-path', '/tmp/tmpc7cxmmau', '--error-file', '/tmp/tmpadhhhuk6']
[2021-07-14 13:34:07,915] {standard_task_runner.py:77} INFO - Job 192: Subtask extract_trends
[2021-07-14 13:34:08,219] {logging_mixin.py:104} INFO - Running <TaskInstance: psotgrressdftest.extract_trends 2021-07-14T13:33:48.199928+00:00 [running]> on host a2cbcfd4d6f4
[2021-07-14 13:34:08,743] {taskinstance.py:1282} INFO - Exporting the following env vars:
AIRFLOW_CTX_DAG_OWNER=***
AIRFLOW_CTX_DAG_ID=psotgrressdftest
AIRFLOW_CTX_TASK_ID=extract_trends
AIRFLOW_CTX_EXECUTION_DATE=2021-07-14T13:33:48.199928+00:00
AIRFLOW_CTX_DAG_RUN_ID=manual__2021-07-14T13:33:48.199928+00:00
[2021-07-14 13:34:08,746] {logging_mixin.py:104} INFO - AAPL
[2021-07-14 13:34:14,022] {taskinstance.py:1481} ERROR - Task failed with exception
Traceback (most recent call last):
  File "/home/airflow/.local/lib/python3.6/site-packages/airflow/models/taskinstance.py", line 1137, in _run_raw_task
    self._prepare_and_execute_task_with_callbacks(context, task)
  File "/home/airflow/.local/lib/python3.6/site-packages/airflow/models/taskinstance.py", line 1311, in _prepare_and_execute_task_with_callbacks
    result = self._execute_task(context, task_copy)
  File "/home/airflow/.local/lib/python3.6/site-packages/airflow/models/taskinstance.py", line 1341, in _execute_task
    result = task_copy.execute(context=context)
  File "/home/airflow/.local/lib/python3.6/site-packages/airflow/operators/python.py", line 150, in execute
    return_value = self.execute_callable()
  File "/home/airflow/.local/lib/python3.6/site-packages/airflow/operators/python.py", line 161, in execute_callable
    return self.python_callable(*self.op_args, **self.op_kwargs)
  File "/opt/airflow/dags/POSTGRESRSERS.py", line 143, in extract_trends
    data = pytrends.interest_over_time()
  File "/home/airflow/.local/lib/python3.6/site-packages/pytrends/request.py", line 234, in interest_over_time
    result_df[idx].astype('int'))
  File "/home/airflow/.local/lib/python3.6/site-packages/pandas/core/frame.py", line 3628, in insert
    self._mgr.insert(loc, column, value, allow_duplicates=allow_duplicates)
  File "/home/airflow/.local/lib/python3.6/site-packages/pandas/core/internals/managers.py", line 1186, in insert
    raise ValueError(f"cannot insert {item}, already exists")
ValueError: cannot insert A, already exists
[2021-07-14 13:34:14,240] {taskinstance.py:1531} INFO - Marking task as FAILED. dag_id=psotgrressdftest, task_id=extract_trends, execution_date=20210714T133348, start_date=20210714T133406, end_date=20210714T133414
[2021-07-14 13:34:14,566] {local_task_job.py:151} INFO - Task exited with return code 1
