[2021-07-14 14:32:22,517] {taskinstance.py:876} INFO - Dependencies all met for <TaskInstance: psotgrressdftest.transform_trends 2021-07-14T14:31:57.416571+00:00 [queued]>
[2021-07-14 14:32:22,598] {taskinstance.py:876} INFO - Dependencies all met for <TaskInstance: psotgrressdftest.transform_trends 2021-07-14T14:31:57.416571+00:00 [queued]>
[2021-07-14 14:32:22,600] {taskinstance.py:1067} INFO - 
--------------------------------------------------------------------------------
[2021-07-14 14:32:22,601] {taskinstance.py:1068} INFO - Starting attempt 1 of 1
[2021-07-14 14:32:22,603] {taskinstance.py:1069} INFO - 
--------------------------------------------------------------------------------
[2021-07-14 14:32:22,637] {taskinstance.py:1087} INFO - Executing <Task(PythonOperator): transform_trends> on 2021-07-14T14:31:57.416571+00:00
[2021-07-14 14:32:22,689] {standard_task_runner.py:52} INFO - Started process 5058 to run task
[2021-07-14 14:32:22,727] {standard_task_runner.py:76} INFO - Running: ['***', 'tasks', 'run', 'psotgrressdftest', 'transform_trends', '2021-07-14T14:31:57.416571+00:00', '--job-id', '283', '--pool', 'default_pool', '--raw', '--subdir', 'DAGS_FOLDER/POSTGRESRSERS.py', '--cfg-path', '/tmp/tmpe8ymrjt6', '--error-file', '/tmp/tmpwk_nsvm0']
[2021-07-14 14:32:22,729] {standard_task_runner.py:77} INFO - Job 283: Subtask transform_trends
[2021-07-14 14:32:22,923] {logging_mixin.py:104} INFO - Running <TaskInstance: psotgrressdftest.transform_trends 2021-07-14T14:31:57.416571+00:00 [running]> on host a2cbcfd4d6f4
[2021-07-14 14:32:23,158] {taskinstance.py:1282} INFO - Exporting the following env vars:
AIRFLOW_CTX_DAG_OWNER=***
AIRFLOW_CTX_DAG_ID=psotgrressdftest
AIRFLOW_CTX_TASK_ID=transform_trends
AIRFLOW_CTX_EXECUTION_DATE=2021-07-14T14:31:57.416571+00:00
AIRFLOW_CTX_DAG_RUN_ID=manual__2021-07-14T14:31:57.416571+00:00
[2021-07-14 14:32:23,306] {taskinstance.py:1481} ERROR - Task failed with exception
Traceback (most recent call last):
  File "/home/airflow/.local/lib/python3.6/site-packages/airflow/models/taskinstance.py", line 1137, in _run_raw_task
    self._prepare_and_execute_task_with_callbacks(context, task)
  File "/home/airflow/.local/lib/python3.6/site-packages/airflow/models/taskinstance.py", line 1311, in _prepare_and_execute_task_with_callbacks
    result = self._execute_task(context, task_copy)
  File "/home/airflow/.local/lib/python3.6/site-packages/airflow/models/taskinstance.py", line 1341, in _execute_task
    result = task_copy.execute(context=context)
  File "/home/airflow/.local/lib/python3.6/site-packages/airflow/operators/python.py", line 150, in execute
    return_value = self.execute_callable()
  File "/home/airflow/.local/lib/python3.6/site-packages/airflow/operators/python.py", line 161, in execute_callable
    return self.python_callable(*self.op_args, **self.op_kwargs)
  File "/opt/airflow/dags/POSTGRESRSERS.py", line 169, in transform_trends
    cur.execute(create_table)
psycopg2.ProgrammingError: schema "googletrends_aarvi" does not exist
LINE 1: Create table IF NOT EXISTS googleTrends_AARVI.NS(date DATE D...
                                   ^

[2021-07-14 14:32:23,377] {taskinstance.py:1531} INFO - Marking task as FAILED. dag_id=psotgrressdftest, task_id=transform_trends, execution_date=20210714T143157, start_date=20210714T143222, end_date=20210714T143223
[2021-07-14 14:32:23,477] {local_task_job.py:151} INFO - Task exited with return code 1
