[2021-07-12 14:30:50,361] {taskinstance.py:876} INFO - Dependencies all met for <TaskInstance: ticker_yahoo.extract_task 2021-07-12T14:30:44.622319+00:00 [queued]>
[2021-07-12 14:30:50,629] {taskinstance.py:876} INFO - Dependencies all met for <TaskInstance: ticker_yahoo.extract_task 2021-07-12T14:30:44.622319+00:00 [queued]>
[2021-07-12 14:30:50,633] {taskinstance.py:1067} INFO - 
--------------------------------------------------------------------------------
[2021-07-12 14:30:50,634] {taskinstance.py:1068} INFO - Starting attempt 1 of 2
[2021-07-12 14:30:50,636] {taskinstance.py:1069} INFO - 
--------------------------------------------------------------------------------
[2021-07-12 14:30:50,721] {taskinstance.py:1087} INFO - Executing <Task(PythonOperator): extract_task> on 2021-07-12T14:30:44.622319+00:00
[2021-07-12 14:30:50,760] {standard_task_runner.py:52} INFO - Started process 3531 to run task
[2021-07-12 14:30:50,790] {standard_task_runner.py:76} INFO - Running: ['***', 'tasks', 'run', 'ticker_yahoo', 'extract_task', '2021-07-12T14:30:44.622319+00:00', '--job-id', '29', '--pool', 'default_pool', '--raw', '--subdir', 'DAGS_FOLDER/seleniumtest.py', '--cfg-path', '/tmp/tmplarf_i8w', '--error-file', '/tmp/tmpjwrkxd0y']
[2021-07-12 14:30:50,804] {standard_task_runner.py:77} INFO - Job 29: Subtask extract_task
[2021-07-12 14:30:51,193] {logging_mixin.py:104} INFO - Running <TaskInstance: ticker_yahoo.extract_task 2021-07-12T14:30:44.622319+00:00 [running]> on host f29b1d03ad56
[2021-07-12 14:30:51,524] {taskinstance.py:1282} INFO - Exporting the following env vars:
AIRFLOW_CTX_DAG_OWNER=***
AIRFLOW_CTX_DAG_ID=ticker_yahoo
AIRFLOW_CTX_TASK_ID=extract_task
AIRFLOW_CTX_EXECUTION_DATE=2021-07-12T14:30:44.622319+00:00
AIRFLOW_CTX_DAG_RUN_ID=manual__2021-07-12T14:30:44.622319+00:00
[2021-07-12 14:32:53,297] {taskinstance.py:1481} ERROR - Task failed with exception
Traceback (most recent call last):
  File "/home/airflow/.local/lib/python3.6/site-packages/airflow/models/taskinstance.py", line 1137, in _run_raw_task
    self._prepare_and_execute_task_with_callbacks(context, task)
  File "/home/airflow/.local/lib/python3.6/site-packages/airflow/models/taskinstance.py", line 1311, in _prepare_and_execute_task_with_callbacks
    result = self._execute_task(context, task_copy)
  File "/home/airflow/.local/lib/python3.6/site-packages/airflow/models/taskinstance.py", line 1341, in _execute_task
    result = task_copy.execute(context=context)
  File "/home/airflow/.local/lib/python3.6/site-packages/airflow/operators/python.py", line 150, in execute
    return_value = self.execute_callable()
  File "/home/airflow/.local/lib/python3.6/site-packages/airflow/operators/python.py", line 161, in execute_callable
    return self.python_callable(*self.op_args, **self.op_kwargs)
  File "/opt/airflow/dags/seleniumtest.py", line 64, in extract
    cur.execute("INSERT INTO tickers1 values ('" + ticker + "','" + companyname + "')")
psycopg2.DataError: invalid input syntax for type integer: "20MICRONS.BO"
LINE 1: INSERT INTO tickers1 values ('20MICRONS.BO','20 Microns Limi...
                                     ^

[2021-07-12 14:32:53,325] {taskinstance.py:1531} INFO - Marking task as UP_FOR_RETRY. dag_id=ticker_yahoo, task_id=extract_task, execution_date=20210712T143044, start_date=20210712T143050, end_date=20210712T143253
[2021-07-12 14:32:53,563] {local_task_job.py:151} INFO - Task exited with return code 1
