[2021-07-13 06:59:02,059] {taskinstance.py:876} INFO - Dependencies all met for <TaskInstance: psotgrressdftest.news_postgres_table 2021-07-13T06:58:16.400663+00:00 [queued]>
[2021-07-13 06:59:02,091] {taskinstance.py:876} INFO - Dependencies all met for <TaskInstance: psotgrressdftest.news_postgres_table 2021-07-13T06:58:16.400663+00:00 [queued]>
[2021-07-13 06:59:02,092] {taskinstance.py:1067} INFO - 
--------------------------------------------------------------------------------
[2021-07-13 06:59:02,093] {taskinstance.py:1068} INFO - Starting attempt 1 of 1
[2021-07-13 06:59:02,094] {taskinstance.py:1069} INFO - 
--------------------------------------------------------------------------------
[2021-07-13 06:59:02,112] {taskinstance.py:1087} INFO - Executing <Task(PythonOperator): news_postgres_table> on 2021-07-13T06:58:16.400663+00:00
[2021-07-13 06:59:02,126] {standard_task_runner.py:52} INFO - Started process 1265 to run task
[2021-07-13 06:59:02,132] {standard_task_runner.py:76} INFO - Running: ['***', 'tasks', 'run', 'psotgrressdftest', 'news_postgres_table', '2021-07-13T06:58:16.400663+00:00', '--job-id', '60', '--pool', 'default_pool', '--raw', '--subdir', 'DAGS_FOLDER/POSTGRESRSERS.py', '--cfg-path', '/tmp/tmpivjgs50r', '--error-file', '/tmp/tmpkf05hmkw']
[2021-07-13 06:59:02,133] {standard_task_runner.py:77} INFO - Job 60: Subtask news_postgres_table
[2021-07-13 06:59:02,209] {logging_mixin.py:104} INFO - Running <TaskInstance: psotgrressdftest.news_postgres_table 2021-07-13T06:58:16.400663+00:00 [running]> on host a2cbcfd4d6f4
[2021-07-13 06:59:02,302] {taskinstance.py:1282} INFO - Exporting the following env vars:
AIRFLOW_CTX_DAG_OWNER=***
AIRFLOW_CTX_DAG_ID=psotgrressdftest
AIRFLOW_CTX_TASK_ID=news_postgres_table
AIRFLOW_CTX_EXECUTION_DATE=2021-07-13T06:58:16.400663+00:00
AIRFLOW_CTX_DAG_RUN_ID=manual__2021-07-13T06:58:16.400663+00:00
[2021-07-13 06:59:02,339] {taskinstance.py:1481} ERROR - Task failed with exception
Traceback (most recent call last):
  File "/home/airflow/.local/lib/python3.6/site-packages/airflow/models/taskinstance.py", line 1137, in _run_raw_task
    self._prepare_and_execute_task_with_callbacks(context, task)
  File "/home/airflow/.local/lib/python3.6/site-packages/airflow/models/taskinstance.py", line 1311, in _prepare_and_execute_task_with_callbacks
    result = self._execute_task(context, task_copy)
  File "/home/airflow/.local/lib/python3.6/site-packages/airflow/models/taskinstance.py", line 1341, in _execute_task
    result = task_copy.execute(context=context)
  File "/home/airflow/.local/lib/python3.6/site-packages/airflow/operators/python.py", line 150, in execute
    return_value = self.execute_callable()
  File "/home/airflow/.local/lib/python3.6/site-packages/airflow/operators/python.py", line 161, in execute_callable
    return self.python_callable(*self.op_args, **self.op_kwargs)
  File "/opt/airflow/dags/POSTGRESRSERS.py", line 79, in news_postgres_table
    cur.execute(create_table)
psycopg2.ProgrammingError: schema "newssentiments_20microns" does not exist
LINE 1: CREATE TABLE IF NOT EXISTS newsSentiments_20MICRONS.BO(news ...
                                   ^

[2021-07-13 06:59:02,355] {taskinstance.py:1531} INFO - Marking task as FAILED. dag_id=psotgrressdftest, task_id=news_postgres_table, execution_date=20210713T065816, start_date=20210713T065902, end_date=20210713T065902
[2021-07-13 06:59:02,424] {local_task_job.py:151} INFO - Task exited with return code 1
