[2021-07-21 11:41:52,236] {taskinstance.py:876} INFO - Dependencies all met for <TaskInstance: psotgrressdftest.tweets_postgres_table 2021-07-21T11:40:36.643245+00:00 [queued]>
[2021-07-21 11:41:58,190] {taskinstance.py:876} INFO - Dependencies all met for <TaskInstance: psotgrressdftest.tweets_postgres_table 2021-07-21T11:40:36.643245+00:00 [queued]>
[2021-07-21 11:41:58,206] {taskinstance.py:1067} INFO - 
--------------------------------------------------------------------------------
[2021-07-21 11:41:58,207] {taskinstance.py:1068} INFO - Starting attempt 1 of 1
[2021-07-21 11:41:58,215] {taskinstance.py:1069} INFO - 
--------------------------------------------------------------------------------
[2021-07-21 11:42:01,781] {taskinstance.py:1087} INFO - Executing <Task(PythonOperator): tweets_postgres_table> on 2021-07-21T11:40:36.643245+00:00
[2021-07-21 11:42:01,867] {standard_task_runner.py:52} INFO - Started process 1647 to run task
[2021-07-21 11:42:01,904] {standard_task_runner.py:76} INFO - Running: ['***', 'tasks', 'run', 'psotgrressdftest', 'tweets_postgres_table', '2021-07-21T11:40:36.643245+00:00', '--job-id', '1993', '--pool', 'default_pool', '--raw', '--subdir', 'DAGS_FOLDER/POSTGRESRSERS.py', '--cfg-path', '/tmp/tmpxkd6fzh_', '--error-file', '/tmp/tmp8dwep9u6']
[2021-07-21 11:42:01,907] {standard_task_runner.py:77} INFO - Job 1993: Subtask tweets_postgres_table
[2021-07-21 11:42:02,275] {logging_mixin.py:104} INFO - Running <TaskInstance: psotgrressdftest.tweets_postgres_table 2021-07-21T11:40:36.643245+00:00 [running]> on host 5795a622f846
[2021-07-21 11:42:08,371] {taskinstance.py:1282} INFO - Exporting the following env vars:
AIRFLOW_CTX_DAG_OWNER=***
AIRFLOW_CTX_DAG_ID=psotgrressdftest
AIRFLOW_CTX_TASK_ID=tweets_postgres_table
AIRFLOW_CTX_EXECUTION_DATE=2021-07-21T11:40:36.643245+00:00
AIRFLOW_CTX_DAG_RUN_ID=manual__2021-07-21T11:40:32.038991+00:00
[2021-07-21 11:42:08,544] {taskinstance.py:1481} ERROR - Task failed with exception
Traceback (most recent call last):
  File "/home/airflow/.local/lib/python3.6/site-packages/airflow/models/taskinstance.py", line 1137, in _run_raw_task
    self._prepare_and_execute_task_with_callbacks(context, task)
  File "/home/airflow/.local/lib/python3.6/site-packages/airflow/models/taskinstance.py", line 1311, in _prepare_and_execute_task_with_callbacks
    result = self._execute_task(context, task_copy)
  File "/home/airflow/.local/lib/python3.6/site-packages/airflow/models/taskinstance.py", line 1341, in _execute_task
    result = task_copy.execute(context=context)
  File "/home/airflow/.local/lib/python3.6/site-packages/airflow/operators/python.py", line 150, in execute
    return_value = self.execute_callable()
  File "/home/airflow/.local/lib/python3.6/site-packages/airflow/operators/python.py", line 161, in execute_callable
    return self.python_callable(*self.op_args, **self.op_kwargs)
  File "/opt/airflow/dags/POSTGRESRSERS.py", line 238, in tweets_postgres_table
    cur.execute(d)
psycopg2.ProgrammingError: relation "tweetssentiments_a2zinfra_bo" does not exist
LINE 1: select * from tweetsSentiments_A2ZINFRA_BO
                      ^

[2021-07-21 11:42:09,204] {taskinstance.py:1531} INFO - Marking task as FAILED. dag_id=psotgrressdftest, task_id=tweets_postgres_table, execution_date=20210721T114036, start_date=20210721T114152, end_date=20210721T114209
[2021-07-21 11:42:10,423] {local_task_job.py:151} INFO - Task exited with return code 1
