[2021-07-15 13:54:59,154] {taskinstance.py:876} INFO - Dependencies all met for <TaskInstance: maintest.testtask 2021-07-15T13:54:57.633786+00:00 [queued]>
[2021-07-15 13:54:59,174] {taskinstance.py:876} INFO - Dependencies all met for <TaskInstance: maintest.testtask 2021-07-15T13:54:57.633786+00:00 [queued]>
[2021-07-15 13:54:59,175] {taskinstance.py:1067} INFO - 
--------------------------------------------------------------------------------
[2021-07-15 13:54:59,175] {taskinstance.py:1068} INFO - Starting attempt 1 of 1
[2021-07-15 13:54:59,179] {taskinstance.py:1069} INFO - 
--------------------------------------------------------------------------------
[2021-07-15 13:54:59,201] {taskinstance.py:1087} INFO - Executing <Task(PythonOperator): testtask> on 2021-07-15T13:54:57.633786+00:00
[2021-07-15 13:54:59,211] {standard_task_runner.py:52} INFO - Started process 3577 to run task
[2021-07-15 13:54:59,216] {standard_task_runner.py:76} INFO - Running: ['***', 'tasks', 'run', 'maintest', 'testtask', '2021-07-15T13:54:57.633786+00:00', '--job-id', '416', '--pool', 'default_pool', '--raw', '--subdir', 'DAGS_FOLDER/tablecreation.py', '--cfg-path', '/tmp/tmpt6gal14_', '--error-file', '/tmp/tmpkojm65m6']
[2021-07-15 13:54:59,217] {standard_task_runner.py:77} INFO - Job 416: Subtask testtask
[2021-07-15 13:54:59,279] {logging_mixin.py:104} INFO - Running <TaskInstance: maintest.testtask 2021-07-15T13:54:57.633786+00:00 [running]> on host a2cbcfd4d6f4
[2021-07-15 13:54:59,363] {taskinstance.py:1282} INFO - Exporting the following env vars:
AIRFLOW_CTX_DAG_OWNER=***
AIRFLOW_CTX_DAG_ID=maintest
AIRFLOW_CTX_TASK_ID=testtask
AIRFLOW_CTX_EXECUTION_DATE=2021-07-15T13:54:57.633786+00:00
AIRFLOW_CTX_DAG_RUN_ID=manual__2021-07-15T13:54:57.633786+00:00
[2021-07-15 13:54:59,384] {taskinstance.py:1481} ERROR - Task failed with exception
Traceback (most recent call last):
  File "/home/airflow/.local/lib/python3.6/site-packages/airflow/models/taskinstance.py", line 1137, in _run_raw_task
    self._prepare_and_execute_task_with_callbacks(context, task)
  File "/home/airflow/.local/lib/python3.6/site-packages/airflow/models/taskinstance.py", line 1311, in _prepare_and_execute_task_with_callbacks
    result = self._execute_task(context, task_copy)
  File "/home/airflow/.local/lib/python3.6/site-packages/airflow/models/taskinstance.py", line 1341, in _execute_task
    result = task_copy.execute(context=context)
  File "/home/airflow/.local/lib/python3.6/site-packages/airflow/operators/python.py", line 150, in execute
    return_value = self.execute_callable()
  File "/home/airflow/.local/lib/python3.6/site-packages/airflow/operators/python.py", line 161, in execute_callable
    return self.python_callable(*self.op_args, **self.op_kwargs)
  File "/opt/airflow/dags/tablecreation.py", line 27, in select_ticker
    cur.execute("CREATE TABLE tickers1 (ID SERIAL, keyword VARCHAR(255) NOT NULL, companyName VARCHAR(255)")
psycopg2.ProgrammingError: syntax error at end of input
LINE 1: ...IAL, keyword VARCHAR(255) NOT NULL, companyName VARCHAR(255)
                                                                       ^

[2021-07-15 13:54:59,394] {taskinstance.py:1531} INFO - Marking task as FAILED. dag_id=maintest, task_id=testtask, execution_date=20210715T135457, start_date=20210715T135459, end_date=20210715T135459
[2021-07-15 13:54:59,519] {local_task_job.py:151} INFO - Task exited with return code 1
