[2021-07-13 07:02:33,702] {taskinstance.py:876} INFO - Dependencies all met for <TaskInstance: psotgrressdftest.transform_trends 2021-07-13T07:02:28.842894+00:00 [queued]>
[2021-07-13 07:02:33,786] {taskinstance.py:876} INFO - Dependencies all met for <TaskInstance: psotgrressdftest.transform_trends 2021-07-13T07:02:28.842894+00:00 [queued]>
[2021-07-13 07:02:33,788] {taskinstance.py:1067} INFO - 
--------------------------------------------------------------------------------
[2021-07-13 07:02:33,790] {taskinstance.py:1068} INFO - Starting attempt 1 of 1
[2021-07-13 07:02:33,791] {taskinstance.py:1069} INFO - 
--------------------------------------------------------------------------------
[2021-07-13 07:02:33,841] {taskinstance.py:1087} INFO - Executing <Task(PythonOperator): transform_trends> on 2021-07-13T07:02:28.842894+00:00
[2021-07-13 07:02:33,864] {standard_task_runner.py:52} INFO - Started process 1526 to run task
[2021-07-13 07:02:33,874] {standard_task_runner.py:76} INFO - Running: ['***', 'tasks', 'run', 'psotgrressdftest', 'transform_trends', '2021-07-13T07:02:28.842894+00:00', '--job-id', '68', '--pool', 'default_pool', '--raw', '--subdir', 'DAGS_FOLDER/POSTGRESRSERS.py', '--cfg-path', '/tmp/tmpaiyeoeac', '--error-file', '/tmp/tmp2ll3usau']
[2021-07-13 07:02:33,876] {standard_task_runner.py:77} INFO - Job 68: Subtask transform_trends
[2021-07-13 07:02:33,994] {logging_mixin.py:104} INFO - Running <TaskInstance: psotgrressdftest.transform_trends 2021-07-13T07:02:28.842894+00:00 [running]> on host a2cbcfd4d6f4
[2021-07-13 07:02:34,162] {taskinstance.py:1282} INFO - Exporting the following env vars:
AIRFLOW_CTX_DAG_OWNER=***
AIRFLOW_CTX_DAG_ID=psotgrressdftest
AIRFLOW_CTX_TASK_ID=transform_trends
AIRFLOW_CTX_EXECUTION_DATE=2021-07-13T07:02:28.842894+00:00
AIRFLOW_CTX_DAG_RUN_ID=manual__2021-07-13T07:02:28.842894+00:00
[2021-07-13 07:02:34,186] {taskinstance.py:1481} ERROR - Task failed with exception
Traceback (most recent call last):
  File "/home/airflow/.local/lib/python3.6/site-packages/airflow/models/taskinstance.py", line 1137, in _run_raw_task
    self._prepare_and_execute_task_with_callbacks(context, task)
  File "/home/airflow/.local/lib/python3.6/site-packages/airflow/models/taskinstance.py", line 1311, in _prepare_and_execute_task_with_callbacks
    result = self._execute_task(context, task_copy)
  File "/home/airflow/.local/lib/python3.6/site-packages/airflow/models/taskinstance.py", line 1341, in _execute_task
    result = task_copy.execute(context=context)
  File "/home/airflow/.local/lib/python3.6/site-packages/airflow/operators/python.py", line 150, in execute
    return_value = self.execute_callable()
  File "/home/airflow/.local/lib/python3.6/site-packages/airflow/operators/python.py", line 161, in execute_callable
    return self.python_callable(*self.op_args, **self.op_kwargs)
  File "/opt/airflow/dags/POSTGRESRSERS.py", line 118, in transform_trends
    Google_Trends = pd.read_csv('./fromlocal/Google_Trends.csv')
NameError: name 'pd' is not defined
[2021-07-13 07:02:34,210] {taskinstance.py:1531} INFO - Marking task as FAILED. dag_id=psotgrressdftest, task_id=transform_trends, execution_date=20210713T070228, start_date=20210713T070233, end_date=20210713T070234
[2021-07-13 07:02:34,372] {local_task_job.py:151} INFO - Task exited with return code 1
