[2021-07-12 15:08:27,943] {taskinstance.py:876} INFO - Dependencies all met for <TaskInstance: ticker_yahoo.extract_task 2021-07-12T15:08:22.343591+00:00 [queued]>
[2021-07-12 15:08:28,116] {taskinstance.py:876} INFO - Dependencies all met for <TaskInstance: ticker_yahoo.extract_task 2021-07-12T15:08:22.343591+00:00 [queued]>
[2021-07-12 15:08:28,126] {taskinstance.py:1067} INFO - 
--------------------------------------------------------------------------------
[2021-07-12 15:08:28,130] {taskinstance.py:1068} INFO - Starting attempt 1 of 2
[2021-07-12 15:08:28,132] {taskinstance.py:1069} INFO - 
--------------------------------------------------------------------------------
[2021-07-12 15:08:28,204] {taskinstance.py:1087} INFO - Executing <Task(PythonOperator): extract_task> on 2021-07-12T15:08:22.343591+00:00
[2021-07-12 15:08:28,315] {standard_task_runner.py:52} INFO - Started process 5476 to run task
[2021-07-12 15:08:28,351] {standard_task_runner.py:76} INFO - Running: ['***', 'tasks', 'run', 'ticker_yahoo', 'extract_task', '2021-07-12T15:08:22.343591+00:00', '--job-id', '40', '--pool', 'default_pool', '--raw', '--subdir', 'DAGS_FOLDER/seleniumtest.py', '--cfg-path', '/tmp/tmpdzcwlyru', '--error-file', '/tmp/tmpm067rcq1']
[2021-07-12 15:08:28,361] {standard_task_runner.py:77} INFO - Job 40: Subtask extract_task
[2021-07-12 15:08:28,735] {logging_mixin.py:104} INFO - Running <TaskInstance: ticker_yahoo.extract_task 2021-07-12T15:08:22.343591+00:00 [running]> on host f29b1d03ad56
[2021-07-12 15:08:29,220] {taskinstance.py:1282} INFO - Exporting the following env vars:
AIRFLOW_CTX_DAG_OWNER=***
AIRFLOW_CTX_DAG_ID=ticker_yahoo
AIRFLOW_CTX_TASK_ID=extract_task
AIRFLOW_CTX_EXECUTION_DATE=2021-07-12T15:08:22.343591+00:00
AIRFLOW_CTX_DAG_RUN_ID=manual__2021-07-12T15:08:22.343591+00:00
[2021-07-12 15:10:52,788] {logging_mixin.py:104} INFO - []
[2021-07-12 15:10:52,810] {taskinstance.py:1481} ERROR - Task failed with exception
Traceback (most recent call last):
  File "/home/airflow/.local/lib/python3.6/site-packages/airflow/models/taskinstance.py", line 1137, in _run_raw_task
    self._prepare_and_execute_task_with_callbacks(context, task)
  File "/home/airflow/.local/lib/python3.6/site-packages/airflow/models/taskinstance.py", line 1311, in _prepare_and_execute_task_with_callbacks
    result = self._execute_task(context, task_copy)
  File "/home/airflow/.local/lib/python3.6/site-packages/airflow/models/taskinstance.py", line 1341, in _execute_task
    result = task_copy.execute(context=context)
  File "/home/airflow/.local/lib/python3.6/site-packages/airflow/operators/python.py", line 150, in execute
    return_value = self.execute_callable()
  File "/home/airflow/.local/lib/python3.6/site-packages/airflow/operators/python.py", line 161, in execute_callable
    return self.python_callable(*self.op_args, **self.op_kwargs)
  File "/opt/airflow/dags/seleniumtest.py", line 63, in extract
    companyname = str(companyname[0].text)
IndexError: list index out of range
[2021-07-12 15:10:52,883] {taskinstance.py:1531} INFO - Marking task as UP_FOR_RETRY. dag_id=ticker_yahoo, task_id=extract_task, execution_date=20210712T150822, start_date=20210712T150827, end_date=20210712T151052
[2021-07-12 15:10:53,299] {local_task_job.py:151} INFO - Task exited with return code 1
